Workbook

Sheet Legend
A1: Bảng so sánh thí nghiệm — Lab Day 1
A2: Lưu file này thành experiments.xlsx. Mỗi lần chạy là một dòng ở sheet Experiments (số dòng tuỳ bạn, có sẵn 60 dòng). Sheet Seeds và Summary tự tổng hợp.
A4: Quy ước màu
B5: Ô vàng: bạn điền (cấu hình và kết quả đo).
A6: abc | B6: Chữ xanh dương: giá trị đã điền sẵn cho dòng baseline; bạn có thể sửa.
B7: Ô xám: công thức tự tính. Không sửa.
A9: Cách dùng
A10: 1. Sheet Experiments: dòng đầu là baseline mẫu. Điền lr và kết quả; thêm dòng cho mỗi thí nghiệm khác.
A11: 2. Mỗi dòng phải có ảnh riêng figures/<exp_id>.png. Điền tên file vào cột figure_file.
A12: 3. Sheet Seeds: nhập exp_id của các lần chạy baseline với seed khác nhau (đã gợi ý base-s1..3). Sheet tự tính trung bình, σ và 2σ.
A13: 4. Cột beyond_noise cho biết chênh lệch val_macro_f1 so với baseline có vượt 2σ không. Chỉ 'Có' mới là bằng chứng.
A14: 5. Sheet Summary: số dòng theo nhóm và số chủ đề (trong 7) đã được thử.
A16: Từ điển cột (sheet Experiments)
A17: Cột | B17: Ý nghĩa | C17: Cách điền
A18: exp_id | B18: Mã thí nghiệm, duy nhất; trùng tên file ảnh | C18: Tự đặt, ví dụ base-s1, opt-adam-lr1e-3, drop-0.3.
A19: group | B19: Nhóm: baseline | loss | optimizer | hparam | dropout | clipping | amp | init | final | other | C19: Chọn từ danh sách.
A20: description | B20: Bạn đổi gì so với baseline | C20: Một câu.
A21: loss | B21: Hàm mất mát: CE | MSE | C21: Chọn từ danh sách.
A22: optimizer | B22: SGD | SGD+momentum | Adam | AdamW | C22: Chọn từ danh sách.
A23: lr | B23: Tốc độ học η | C23: Ghi số, ví dụ 0.05 hoặc 1e-3.
A24: weight_decay | B24: Hệ số suy giảm trọng số λ | C24: 0 nếu không dùng.
A25: batch | B25: Kích thước lô | C25: Số nguyên.
A26: epochs | B26: Số epoch | C26: Khuyến nghị 20 cho mọi thí nghiệm.
A27: hidden | B27: Các lớp ẩn, ví dụ 256-128 | C27: Chuỗi nối bằng dấu gạch.
A28: dropout | B28: Xác suất tắt nơ-ron q | C28: 0 nếu không dùng.
... A33: step0_loss | B33: Loss trên val ở bước 0 (trước cập nhật đầu tiên) | C33: Kỳ vọng ≈ ln 7 = 1.946 nếu khởi tạo hợp lý.
A34: best_val_loss | B34: Val loss thấp nhất qua các epoch
A35: best_epoch | B35: Epoch đạt best_val_loss | C35: Đếm từ 1.
A36: final_train_loss | B36: Train loss ở epoch cuối (đo ở chế độ eval)
A37: final_val_loss | B37: Val loss ở epoch cuối
A38: val_acc | B38: Val accuracy ở best_epoch | C38: Phân số 0–1, ví dụ 0.8123.
A39: val_macro_f1 | B39: Val macro-F1 ở best_epoch | C39: Phân số 0–1.
A40: time_per_epoch_s | B40: Thời gian trung bình mỗi epoch (giây) | C40: Có torch.cuda.synchronize().
A41: peak_mem_MB | B41: Bộ nhớ GPU cực đại (MB) | C41: torch.cuda.max_memory_allocated()/2**20.
A42: diverged | B42: Loss thành NaN/inf? Y | N | C42: Chọn từ danh sách.
A43: eval_acc | B43: Accuracy trên tập eval | C43: CHỈ điền cho baseline và cấu hình cuối cùng, lấy từ eval_result.json.
A44: eval_macro_f1 | B44: macro-F1 trên tập eval | C44: CHỈ điền cho baseline và cấu hình cuối cùng, lấy từ eval_result.json.
A45: figure_file | B45: Tên file ảnh | C45: figures/<exp_id>.png
A46: notes | B46: Ghi chú | C46: Dự đoán trước, quan sát, lý do thiếu số liệu, lỗi gặp phải...
A47: step0_gap_vs_lnC | B47: step0_loss − ln 7 | C47: Tự tính. Gần 0 là tốt.
...

Sheet Experiments
A1: exp_id | B1: group | C1: description | D1: loss | E1: optimizer | F1: lr | G1: weight_decay | H1: batch | I1: epochs | J1: hidden | K1: dropout | L1: clip_norm | M1: precision | N1: init | O1: seed | P1: step0_loss | Q1: best_val_loss | R1: best_epoch | S1: final_train_loss | T1: final_val_loss | U1: val_acc | V1: val_macro_f1 | W1: time_per_epoch_s | X1: peak_mem_MB | Y1: diverged | Z1: eval_acc | AA1: eval_macro_f1 | AB1: figure_file | AC1: notes | AD1: step0_gap_vs_lnC | AE1: gap_val_minus_train | AF1: delta_val_f1_vs_base | AG1: beyond_noise
A2: base-s1 | B2: baseline | C2: Baseline M-base: SGD+momentum, lr=0.05, He init | D2: ce | E2: sgd_momentum | F2: 0.05 | G2: 0 | H2: 512 | I2: 20 | J2: [256, 128] | K2: 0 | M2: fp32 | N2: he | O2: 1 | P2: 2.2690823 | Q2: 0.25316796 | R2: 19 | S2: 0.24046219 | T2: 0.26082149 | U2: 0.89736664 | V2: 0.84054791 | W2: 1.5050725 | X2: 0 | Y2: FALSE | AB2: figures/base-s1.png
A3: base-s2 | B3: baseline | C3: Baseline M-base: SGD+momentum, lr=0.05, He init | D3: ce | E3: sgd_momentum | F3: 0.05 | G3: 0 | H3: 512 | I3: 20 | J3: [256, 128] | K3: 0 | M3: fp32 | N3: he | O3: 2 | P3: 1.9781686 | Q3: 0.24685004 | R3: 20 | S3: 0.22609259 | T3: 0.24685004 | U3: 0.90037864 | V3: 0.83759705 | W3: 1.8824869 | X3: 0 | Y3: FALSE | AB3: figures/base-s2.png
A4: base-s3 | B4: baseline | C4: Baseline M-base: SGD+momentum, lr=0.05, He init | D4: ce | E4: sgd_momentum | F4: 0.05 | G4: 0 | H4: 512 | I4: 20 | J4: [256, 128] | K4: 0 | M4: fp32 | N4: he | O4: 3 | P4: 1.9005361 | Q4: 0.24812573 | R4: 19 | S4: 0.23466119 | T4: 0.25470638 | U4: 0.90051848 | V4: 0.84379064 | W4: 1.8151738 | X4: 0 | Y4: FALSE | AB4: figures/base-s3.png
A5: clip-1.0-highlr | B5: clipping | C5: Clip norm=1.0, high lr | D5: ce | E5: sgd_momentum | F5: 0.1 | G5: 0 | H5: 512 | I5: 20 | J5: [256, 128] | K5: 0 | L5: 1 | M5: fp32 | N5: he | O5: 1 | P5: 2.2690823 | Q5: 0.23998179 | R5: 18 | S5: 0.21613204 | T5: 0.24011186 | U5: 0.90264839 | V5: 0.84639924 | W5: 1.4455851 | X5: 0 | Y5: FALSE | AB5: figures/clip-1.0-highlr.png
A6: drop-0.3 | B6: dropout | C6: Dropout q=0.3 | D6: ce | E6: sgd_momentum | F6: 0.05 | G6: 0 | H6: 512 | I6: 20 | J6: [256, 128] | K6: 0.3 | M6: fp32 | N6: he | O6: 1 | P6: 2.2690823 | Q6: 0.34017099 | R6: 20 | S6: 0.33385525 | T6: 0.34017099 | U6: 0.86295474 | V6: 0.76332031 | W6: 2.418326 | X6: 0 | Y6: FALSE | AB6: figures/drop-0.3.png
A7: hparam-wd-0.001 | B7: hparam | C7: Weight decay 0.001 | D7: ce | E7: sgd_momentum | F7: 0.05 | G7: 0.001 | H7: 512 | I7: 20 | J7: [256, 128] | K7: 0 | M7: fp32 | N7: he | O7: 1 | P7: 2.2690823 | Q7: 0.39023364 | R7: 20 | S7: 0.38419248 | T7: 0.39023364 | U7: 0.84104258 | V7: 0.6790349 | W7: 2.1529049 | X7: 0 | Y7: FALSE | AB7: figures/hparam-wd-0.001.png
A8: init-xavier | B8: init | C8: Xavier initialization | D8: ce | E8: sgd_momentum | F8: 0.05 | G8: 0 | H8: 512 | I8: 20 | J8: [256, 128] | K8: 0 | M8: fp32 | N8: xavier | O8: 1 | P8: 2.0221801 | Q8: 0.24467602 | R8: 20 | S8: 0.22690076 | T8: 0.24467602 | U8: 0.90156192 | V8: 0.84254252 | W8: 2.019482 | X8: 0 | Y8: FALSE | AB8: figures/init-xavier.png
A9: loss-mse | B9: loss | C9: MSE loss | D9: mse | E9: sgd_momentum | F9: 0.05 | G9: 0 | H9: 512 | I9: 20 | J9: [256, 128] | K9: 0 | M9: fp32 | N9: he | O9: 1 | P9: 0.63586982 | Q9: 0.032412568 | R9: 20 | S9: 0.031554685 | T9: 0.032412568 | U9: 0.85485464 | V9: 0.68284545 | W9: 1.2681056 | X9: 0 | Y9: FALSE | AB9: figures/loss-mse.png
A10: opt-adam-lr0.001 | B10: optimizer | C10: Adam lr=0.001 | D10: ce | E10: adam | F10: 0.001 | G10: 0 | H10: 512 | I10: 20 | J10: [256, 128] | K10: 0 | M10: fp32 | N10: he | O10: 1 | P10: 2.2690823 | Q10: 0.23963015 | R10: 20 | S10: 0.2188429 | T10: 0.23963015 | U10: 0.90478903 | V10: 0.85134142 | W10: 2.38009 | X10: 0 | Y10: FALSE | AB10: figures/opt-adam-lr0.001.png

Sheet Seeds
A1: exp_id baseline (nhập) | B1: val_acc | C1: val_macro_f1 | D1: best_val_loss
A2: base-s1 | B2: =IF($A2="","",IFERROR(IF(INDEX(Experiments!$U$2:$U$61,MATCH($A2,Experiments!$A$2:$A$61,0))="","",INDEX(Experiments!$U$2:$U$61,MATCH($A2,Experiments!$A$2:$A$61,0))),"")) | C2: =IF($A2="","",IFERROR(IF(INDEX(Experiments!$V$2:$V$61,MATCH($A2,Experiments!$A$2:$A$61,0))="","",INDEX(Experiments!$V$2:$V$61,MATCH($A2,Experiments!$A$2:$A$61,0))),"")) | D2: =IF($A2="","",IFERROR(IF(INDEX(Experiments!$Q$2:$Q$61,MATCH($A2,Experiments!$A$2:$A$61,0))="","",INDEX(Experiments!$Q$2:$Q$61,MATCH($A2,Experiments!$A$2:$A$61,0))),""))
A3: base-s2 | B3: =IF($A3="","",IFERROR(IF(INDEX(Experiments!$U$2:$U$61,MATCH($A3,Experiments!$A$2:$A$61,0))="","",INDEX(Experiments!$U$2:$U$61,MATCH($A3,Experiments!$A$2:$A$61,0))),"")) | C3: =IF($A3="","",IFERROR(IF(INDEX(Experiments!$V$2:$V$61,MATCH($A3,Experiments!$A$2:$A$61,0))="","",INDEX(Experiments!$V$2:$V$61,MATCH($A3,Experiments!$A$2:$A$61,0))),"")) | D3: =IF($A3="","",IFERROR(IF(INDEX(Experiments!$Q$2:$Q$61,MATCH($A3,Experiments!$A$2:$A$61,0))="","",INDEX(Experiments!$Q$2:$Q$61,MATCH($A3,Experiments!$A$2:$A$61,0))),""))
A4: base-s3 | B4: =IF($A4="","",IFERROR(IF(INDEX(Experiments!$U$2:$U$61,MATCH($A4,Experiments!$A$2:$A$61,0))="","",INDEX(Experiments!$U$2:$U$61,MATCH($A4,Experiments!$A$2:$A$61,0))),"")) | C4: =IF($A4="","",IFERROR(IF(INDEX(Experiments!$V$2:$V$61,MATCH($A4,Experiments!$A$2:$A$61,0))="","",INDEX(Experiments!$V$2:$V$61,MATCH($A4,Experiments!$A$2:$A$61,0))),"")) | D4: =IF($A4="","",IFERROR(IF(INDEX(Experiments!$Q$2:$Q$61,MATCH($A4,Experiments!$A$2:$A$61,0))="","",INDEX(Experiments!$Q$2:$Q$61,MATCH($A4,Experiments!$A$2:$A$61,0))),""))
B5: =IF($A5="","",IFERROR(IF(INDEX(Experiments!$U$2:$U$61,MATCH($A5,Experiments!$A$2:$A$61,0))="","",INDEX(Experiments!$U$2:$U$61,MATCH($A5,Experiments!$A$2:$A$61,0))),"")) | C5: =IF($A5="","",IFERROR(IF(INDEX(Experiments!$V$2:$V$61,MATCH($A5,Experiments!$A$2:$A$61,0))="","",INDEX(Experiments!$V$2:$V$61,MATCH($A5,Experiments!$A$2:$A$61,0))),"")) | D5: =IF($A5="","",IFERROR(IF(INDEX(Experiments!$Q$2:$Q$61,MATCH($A5,Experiments!$A$2:$A$61,0))="","",INDEX(Experiments!$Q$2:$Q$61,MATCH($A5,Experiments!$A$2:$A$61,0))),""))
B6: =IF($A6="","",IFERROR(IF(INDEX(Experiments!$U$2:$U$61,MATCH($A6,Experiments!$A$2:$A$61,0))="","",INDEX(Experiments!$U$2:$U$61,MATCH($A6,Experiments!$A$2:$A$61,0))),"")) | C6: =IF($A6="","",IFERROR(IF(INDEX(Experiments!$V$2:$V$61,MATCH($A6,Experiments!$A$2:$A$61,0))="","",INDEX(Experiments!$V$2:$V$61,MATCH($A6,Experiments!$A$2:$A$61,0))),"")) | D6: =IF($A6="","",IFERROR(IF(INDEX(Experiments!$Q$2:$Q$61,MATCH($A6,Experiments!$A$2:$A$61,0))="","",INDEX(Experiments!$Q$2:$Q$61,MATCH($A6,Experiments!$A$2:$A$61,0))),""))
A8: mean | B8: =IF(COUNT(B2:B6)=0,"",AVERAGE(B2:B6)) | C8: =IF(COUNT(C2:C6)=0,"",AVERAGE(C2:C6)) | D8: =IF(COUNT(D2:D6)=0,"",AVERAGE(D2:D6))
A9: std (mẫu) | B9: =IF(COUNT(B2:B6)<2,"",STDEV(B2:B6)) | C9: =IF(COUNT(C2:C6)<2,"",STDEV(C2:C6)) | D9: =IF(COUNT(D2:D6)<2,"",STDEV(D2:D6))
A10: 2σ (ngưỡng nhiễu) | B10: =IF(B9="","",2*B9) | C10: =IF(C9="","",2*C9) | D10: =IF(D9="","",2*D9)
A12: Nhập exp_id của các lần chạy baseline (khác seed) ở cột A. Cần ≥ 2 seed để có σ.
A13: Mọi chênh lệch nhỏ hơn 2σ không được coi là bằng chứng. Với ít seed, σ chỉ là ước lượng thô; nêu rõ trong báo cáo.

Sheet Summary
A1: group | B1: số dòng | C1: đã điền val_macro_f1 | D1: val_macro_f1 cao nhất | E1: val_macro_f1 thấp nhất | F1: val_acc cao nhất | G1: đã thử chủ đề này? | H1: nhận xét ngắn (bạn viết)
A2: baseline | B2: =COUNTIF(Experiments!$B$2:$B$61,A2) | C2: =COUNTIFS(Experiments!$B$2:$B$61,A2,Experiments!$V$2:$V$61,"<>") | D2: =IF(C2=0,"",_xlfn.MAXIFS(Experiments!$V$2:$V$61,Experiments!$B$2:$B$61,A2)) | E2: =IF(C2=0,"",_xlfn.MINIFS(Experiments!$V$2:$V$61,Experiments!$B$2:$B$61,A2)) | F2: =IF(C2=0,"",_xlfn.MAXIFS(Experiments!$U$2:$U$61,Experiments!$B$2:$B$61,A2)) | G2: —
A3: loss | B3: =COUNTIF(Experiments!$B$2:$B$61,A3) | C3: =COUNTIFS(Experiments!$B$2:$B$61,A3,Experiments!$V$2:$V$61,"<>") | D3: =IF(C3=0,"",_xlfn.MAXIFS(Experiments!$V$2:$V$61,Experiments!$B$2:$B$61,A3)) | E3: =IF(C3=0,"",_xlfn.MINIFS(Experiments!$V$2:$V$61,Experiments!$B$2:$B$61,A3)) | F3: =IF(C3=0,"",_xlfn.MAXIFS(Experiments!$U$2:$U$61,Experiments!$B$2:$B$61,A3)) | G3: =IF(C3>0,"Có","Chưa")
A4: optimizer | B4: =COUNTIF(Experiments!$B$2:$B$61,A4) | C4: =COUNTIFS(Experiments!$B$2:$B$61,A4,Experiments!$V$2:$V$61,"<>") | D4: =IF(C4=0,"",_xlfn.MAXIFS(Experiments!$V$2:$V$61,Experiments!$B$2:$B$61,A4)) | E4: =IF(C4=0,"",_xlfn.MINIFS(Experiments!$V$2:$V$61,Experiments!$B$2:$B$61,A4)) | F4: =IF(C4=0,"",_xlfn.MAXIFS(Experiments!$U$2:$U$61,Experiments!$B$2:$B$61,A4)) | G4: =IF(C4>0,"Có","Chưa")
A5: hparam | B5: =COUNTIF(Experiments!$B$2:$B$61,A5) | C5: =COUNTIFS(Experiments!$B$2:$B$61,A5,Experiments!$V$2:$V$61,"<>") | D5: =IF(C5=0,"",_xlfn.MAXIFS(Experiments!$V$2:$V$61,Experiments!$B$2:$B$61,A5)) | E5: =IF(C5=0,"",_xlfn.MINIFS(Experiments!$V$2:$V$61,Experiments!$B$2:$B$61,A5)) | F5: =IF(C5=0,"",_xlfn.MAXIFS(Experiments!$U$2:$U$61,Experiments!$B$2:$B$61,A5)) | G5: =IF(C5>0,"Có","Chưa")
A6: dropout | B6: =COUNTIF(Experiments!$B$2:$B$61,A6) | C6: =COUNTIFS(Experiments!$B$2:$B$61,A6,Experiments!$V$2:$V$61,"<>") | D6: =IF(C6=0,"",_xlfn.MAXIFS(Experiments!$V$2:$V$61,Experiments!$B$2:$B$61,A6)) | E6: =IF(C6=0,"",_xlfn.MINIFS(Experiments!$V$2:$V$61,Experiments!$B$2:$B$61,A6)) | F6: =IF(C6=0,"",_xlfn.MAXIFS(Experiments!$U$2:$U$61,Experiments!$B$2:$B$61,A6)) | G6: =IF(C6>0,"Có","Chưa")
A7: clipping | B7: =COUNTIF(Experiments!$B$2:$B$61,A7) | C7: =COUNTIFS(Experiments!$B$2:$B$61,A7,Experiments!$V$2:$V$61,"<>") | D7: =IF(C7=0,"",_xlfn.MAXIFS(Experiments!$V$2:$V$61,Experiments!$B$2:$B$61,A7)) | E7: =IF(C7=0,"",_xlfn.MINIFS(Experiments!$V$2:$V$61,Experiments!$B$2:$B$61,A7)) | F7: =IF(C7=0,"",_xlfn.MAXIFS(Experiments!$U$2:$U$61,Experiments!$B$2:$B$61,A7)) | G7: =IF(C7>0,"Có","Chưa")
A8: amp | B8: =COUNTIF(Experiments!$B$2:$B$61,A8) | C8: =COUNTIFS(Experiments!$B$2:$B$61,A8,Experiments!$V$2:$V$61,"<>") | D8: =IF(C8=0,"",_xlfn.MAXIFS(Experiments!$V$2:$V$61,Experiments!$B$2:$B$61,A8)) | E8: =IF(C8=0,"",_xlfn.MINIFS(Experiments!$V$2:$V$61,Experiments!$B$2:$B$61,A8)) | F8: =IF(C8=0,"",_xlfn.MAXIFS(Experiments!$U$2:$U$61,Experiments!$B$2:$B$61,A8)) | G8: =IF(C8>0,"Có","Chưa")
A9: init | B9: =COUNTIF(Experiments!$B$2:$B$61,A9) | C9: =COUNTIFS(Experiments!$B$2:$B$61,A9,Experiments!$V$2:$V$61,"<>") | D9: =IF(C9=0,"",_xlfn.MAXIFS(Experiments!$V$2:$V$61,Experiments!$B$2:$B$61,A9)) | E9: =IF(C9=0,"",_xlfn.MINIFS(Experiments!$V$2:$V$61,Experiments!$B$2:$B$61,A9)) | F9: =IF(C9=0,"",_xlfn.MAXIFS(Experiments!$U$2:$U$61,Experiments!$B$2:$B$61,A9)) | G9: =IF(C9>0,"Có","Chưa")
A10: final | B10: =COUNTIF(Experiments!$B$2:$B$61,A10) | C10: =COUNTIFS(Experiments!$B$2:$B$61,A10,Experiments!$V$2:$V$61,"<>") | D10: =IF(C10=0,"",_xlfn.MAXIFS(Experiments!$V$2:$V$61,Experiments!$B$2:$B$61,A10)) | E10: =IF(C10=0,"",_xlfn.MINIFS(Experiments!$V$2:$V$61,Experiments!$B$2:$B$61,A10)) | F10: =IF(C10=0,"",_xlfn.MAXIFS(Experiments!$U$2:$U$61,Experiments!$B$2:$B$61,A10)) | G10: —
A11: other | B11: =COUNTIF(Experiments!$B$2:$B$61,A11) | C11: =COUNTIFS(Experiments!$B$2:$B$61,A11,Experiments!$V$2:$V$61,"<>") | D11: =IF(C11=0,"",_xlfn.MAXIFS(Experiments!$V$2:$V$61,Experiments!$B$2:$B$61,A11)) | E11: =IF(C11=0,"",_xlfn.MINIFS(Experiments!$V$2:$V$61,Experiments!$B$2:$B$61,A11)) | F11: =IF(C11=0,"",_xlfn.MAXIFS(Experiments!$U$2:$U$61,Experiments!$B$2:$B$61,A11)) | G11: —
A13: Số chủ đề (trong 7) đã thử: | D13: =COUNTIF(G2:G11,"Có")
A14: 7 chủ đề: loss, optimizer, hparam, dropout, clipping, amp, init. Một chủ đề 'đã thử' khi có ≥ 1 dòng có val_macro_f1.
